Workbook
Name C_to_CO2: Conversions!$B$5
Name kg_to_m3: Conversions!$B$3
Name t_to_m3: Conversions!$B$2
Name tC_to_m3: Conversions!$B$4

Sheet Sheet1
A1: Metadata | B1: Metadata | C1: Metadata | D1: Metadata | E1: Metadata | F1: Metadata | G1: Metadata | H1: Metadata | I1: Metadata | J1: Metadata | K1: Metadata | L1: Metadata | M1: Metadata | N1: Metadata | O1: Protocol | P1: Protocol | S1: Drivers | T1: Drivers | U1: Drivers | X1: Drivers | Y1: Drivers | Z1: Drivers | AA1: Drivers | AB1: Drivers | AC1: Drivers | AD1: Drivers | AE1: Drivers | AF1: Drivers | AG1: Drivers | AH1: Drivers | AI1: Drivers | AJ1: Drivers | AK1: Drivers | AL1: Drivers | AM1: Drivers | AN1: Drivers | AO1: Drivers | AP1: Drivers | AQ1: Drivers | AR1: Drivers | AS1: Drivers | AT1: Drivers | AU1: Drivers | AV1: Drivers | AW1: Drivers | AX1: Drivers | AY1: Drivers | AZ1: Protocol | BA1: Protocol | BE1: Protocol | BF1: Protocol | BG1: Drivers | BH1: Drivers | BI1: Outcomes | BJ1: Outcomes | BL1: Outcomes | BM1: Outcomes | BN1: Outcomes | BO1: Outcomes | BP1: Outcomes | BQ1: Outcomes | BR1: Outcomes | BT1: Outcomes | BU1: Outcomes | BV1: Outcomes | BW1: Outcomes | BX1: Outcomes | BZ1: Outcomes | CA1: Outcomes | CB1: Outcomes | CC1: Outcomes | CD1: Outcomes | CE1: Outcomes | CF1: Outcomes | CG1: Outcomes | CH1: Outcomes | CI1: Outcomes | CJ1: Outcomes | CK1: Outcomes | CL1: Outcomes | CM1: Outcomes | CN1: Outcomes | CO1: Outcomes | CP1: Outcomes | CQ1: Outcomes | CR1: Outcomes | CS1: Outcomes | CU1: Outcomes | CV1: Outcomes | CW1: Outcomes | CY1: Outcomes | DA1: Outcomes | DB1: Model | DC1: Model | DD1: Model | DE1: Model | DF1: Model | DG1: Model | DH1: Model | DI1: Model | DJ1: Model | DK1: Model | DL1: Model | DM1: Model | DN1: Model | DO1: Model | DP1: Model | DQ1: Model | DR1: Model | DS1: Model | DT1: Model | DU1: Model | DV1: Model | DW1: Model | DX1: Model | DY1: Model | DZ1: Model | EA1: Model | EB1: Model | EC1: Model | ED1: Model | EE1: Model | EF1: Model | EG1: Model | EH1: Model | EI1: Model | EJ1: Model | EK1: Model | EL1: Model | EM1: Model | EN1: Model | EW1: Protocol | EX1: Protocol | EY1: Protocol | EZ1: Protocol | FB1: Protocol | FC1: Protocol
A2: Paper description | B2: Paper description | C2: Paper description | D2: Paper description | E2: Paper description | F2: Paper description | G2: Paper description | H2: Paper description | I2: Paper description | J2: Paper description | K2: Paper description | L2: Paper description | M2: Paper description | N2: Protocol | O2: Extraction | P2: Post-extraction | Q2: Extraction round | S2: Driver | T2: Driver | U2: Driver | X2: Change in practices | Y2: Change in practices | Z2: Change in practices | AA2: Change in practices | AB2: Change in practices | AC2: Change in practices | AD2: Change in practices | AE2: Change in practices | AF2: Change in practices | AG2: Change in practices | AH2: Change in practices | AI2: Change in practices | AJ2: Change in practices | AK2: Change in practices | AL2: Change in practices | AM2: Change in practices | AN2: Change in practices | AO2: Environmental change | AP2: Environmental change | AQ2: Environmental change | AR2: Environmental change | AS2: Environmental change | AT2: Environmental change | AU2: Environmental change | AV2: Environmental change | AW2: Environmental change | AX2: Environmental change | AY2: Environmental change | AZ2: Post-extraction | BA2: QC | BE2: QC | BF2: QC | BG2: DataCorrection | BH2: DataCorrection | BI2: Carbon_outcome | BJ2: Carbon_outcome | BL2: Carbon_outcome | BM2: Carbon_outcome | BN2: Carbon_outcome | BO2: Carbon_outcome | BP2: Carbon_outcome | BQ2: Carbon_outcome | BR2: Carbon_outcome | BT2: Carbon_outcome | BU2: Carbon_outcome | BV2: Carbon_outcome | BW2: Carbon_outcome | BX2: Carbon_outcome | BZ2: Carbon_outcome | CB2: Non_c_outcomes | CC2: Non_c_outcomes | CD2: Non_c_outcomes | CE2: Non_c_outcomes | CF2: Non_c_outcomes | CG2: Non_c_outcomes | CH2: Non_c_outcomes | CI2: Non_c_outcomes | CJ2: Non_c_outcomes | CK2: Non_c_outcomes | CL2: Non_c_outcomes | CM2: Non_c_outcomes | CN2: Non_c_outcomes | CO2: Non_c_outcomes | CP2: DataCorrection | CQ2: DataCorrection | CR2: DataCorrection | CS2: DataCorrection | CU2: DataCorrection | CV2: DataCorrection | CW2: DataCorrection | CY2: DataCorrection | DA2: DataCorrection | DB2: Context definition | DC2: DataCorrection | DD2: DataCorrection | DE2: Context definition | DF2: Context definition | DG2: Context definition | DH2: DataCorrection | DI2: Context definition | DJ2: Context definition | DK2: Context definition | DL2: Context definition | DM2: Context definition | DN2: QC | DO2: DataCorrection | DP2: Context definition | DQ2: Context definition | DR2: Context definition | DS2: Context definition | DT2: Processes | DU2: Processes | DV2: ProcessesDetails | DW2: ProcessesDetails | DX2: ProcessesDetails | DY2: QC | DZ2: Post-extraction | EA2: Processes | EB2: Processes | EC2: Processes | ED2: Processes | EE2: Processes | EF2: Processes | EG2: Processes | EH2: Processes | EI2: Processes | EJ2: Processes | EK2: Processes | EL2: Processes | EM2: Processes | EN2: Processes | EW2: Post-extraction | EX2: Post-extraction | EY2: Post-extraction | EZ2: Post-extraction | FB2: Post-extraction | FC2: QC
X3: #CAACCB | Y3: #CAACCB | Z3: #CAACCB | AA3: #CAACCB | AB3: #CAACCB | AC3: #CAACCB | AD3: #CAACCB | AE3: #CAACCB | AF3: #CAACCB | AG3: #CAACCB | AH3: #CAACCB | AI3: #CAACCB | AJ3: #CAACCB | AK3: #CAACCB | AL3: #CAACCB | AM3: #CAACCB | AN3: #CAACCB | AO3: #994F93 | AP3: #994F93 | AQ3: #994F93 | AR3: #994F93 | AS3: #994F93 | AT3: #994F93 | AU3: #994F93 | AV3: #994F93 | AW3: #994F93 | AX3: #994F93 | AY3: #994F93 | DN3: #77777 | DT3: #90C987 | DU3: #90C987 | DV3: #90C987 | DW3: #90C987 | DX3: #90C987 | DY3: #77777 | EA3: #90C987 | EB3: #90C987 | EC3: #90C987 | ED3: #90C987 | EE3: #90C987 | EF3: #90C987 | EG3: #90C987 | EH3: #90C987 | EI3: #90C987 | EJ3: #90C987 | EK3: #90C988 | EL3: #90C989 | EM3: #90C990 | EN3: #90C991
A4: Publication | B4: Topic | C4: Topic | D4: Authors | E4: Topic | F4: Topic | G4: Journal | H4: Publication | I4: Publication | J4: Publication | K4: Publication | L4: Publication | M4: Authors | N4: Exclusion | O4: Full revision | P4: Revision | S4: driver description | T4: driver description | U4: driver description | V4: Silviculture for removals | X4: Silviculture for removals | Y4: Silviculture for removals | Z4: Silviculture for removals | AA4: Silviculture for removals | AB4: Silviculture for productivity | AC4: Silviculture for productivity | AD4: Silviculture for productivity | AE4: Silviculture for productivity | AF4: Supply chain | AG4: Supply chain | AH4: Supply chain | AI4: Supply chain | AJ4: Supply chain | AK4: Supply chain | AL4: Technology | AM4: Technology | AN4: Technology | AO4: Environmental change | AP4: Environmental change | AQ4: Environmental change | AR4: Environmental change | AS4: Environmental change | AT4: Environmental change | AU4: Demand | AV4: Demand | AW4: Demand | AX4: Demand | AY4: Demand | AZ4: QC | BA4: All | BE4: AllEnvir | BF4: AllEnvir | BG4: MainDriver | BH4: MainDriver | BI4: Wood amount | BJ4: Wood amount | BL4: Wood amount | BM4: Wood amount | BN4: Wood amount | BO4: Wood amount | BP4: Wood amount | BQ4: Wood amount | BR4: Cumulated C balance | BS4: Cumulated C balance | BT4: Cumulated C balance | BU4: Cumulated C balance | BV4: Cumulated C balance | BW4: Cumulated C balance | BX4: Cumulated C balance | BZ4: Cumulated C balance | CA4: Substitution coefficient | CB4: LCAOutcomes | CC4: biogeochemicalOutcomes | CD4: biogeochemicalOutcomes | CE4: biogeochemicalOutcomes | CF4: biogeochemicalOutcomes | CG4: biogeochemicalOutcomes | CH4: biogeochemicalOutcomes | CI4: biophysicalOutcomes | CJ4: biophysicalOutcomes | CK4: biophysicalOutcomes | CL4: biophysicalOutcomes | CM4: biophysicalOutcomes | CN4: ecologicalOutcomes | CO4: economicalOutcomes | CP4: driver description | CQ4: Wood amount | CR4: Carbon_outcome | CS4: Carbon_outcome | CU4: Carbon_outcome | CV4: Carbon_outcome | CW4: Carbon_outcome | CY4: Carbon_outcome | DA4: Carbon_outcome | DB4: Location | DC4: Location | DD4: Location | DE4: Time period | DF4: Time period | DG4: Time period | DI4: Wood affected by driver change | DJ4: Wood affected by driver change | DK4: Wood affected by driver change | DL4: Wood affected by driver change | DM4: Sector scale | DN4: QC | DO4: Wood affected by driver change | DP4: Wood affected by driver change | DQ4: Wood affected by driver change | DR4: Wood affected by driver change | DS4: Wood affected by driver change | DT4: SubstitutionShortcut | DU4: SubstitutionShortcut | DV4: SubstitutionShortcut | DW4: SubstitutionShortcut | DX4: SubstitutionShortcut | DY4: QC | DZ4: SubstitutionShortcut | EA4: C fluxes | EB4: C fluxes | EC4: C fluxes | ED4: C fluxes | EE4: C fluxes | EF4: C fluxes | EG4: C fluxes | EH4: C fluxes | EI4: C fluxes | EJ4: C fluxes | EK4: Dynamics | EL4: Dynamics | EM4: Dynamics | EN4: Dynamics | EW4: QC | EX4: QC | EY4: QC | EZ4: QC | FB4: QC | FC4: DriverCheck
V5: #D9CCE3 | W5: #D9CCE3 | X5: #D9CCE3 | Y5: #D9CCE3 | Z5: #D9CCE3 | AA5: #D9CCE3 | AB5: #D9CCE3 | AC5: #D9CCE3 | AD5: #D9CCE3 | AE5: #D9CCE3 | AF5: #CAACCB | AG5: #CAACCB | AH5: #CAACCB | AI5: #CAACCB | AJ5: #CAACCB | AK5: #CAACCB | AL5: #BA8DB4 | AM5: #BA8DB4 | AN5: #BA8DB4 | AO5: #994F88 | AP5: #994F88 | AQ5: #994F88 | AR5: #994F88 | AS5: #994F88 | AT5: #994F88 | AU5: #882E72 | AV5: #882E72 | AW5: #882E72 | AX5: #882E72 | AY5: #882E72 | DN5: #77777 | DT5: #CAE0AB | DU5: #CAE0AB | DV5: #CAE0AB | DW5: #CAE0AB | DX5: #CAE0AB | DY5: #77777 | EA5: #90C987 | EB5: #90C987 | EC5: #90C987 | ED5: #90C987 | EE5: #90C987 | EF5: #90C987 | EG5: #90C987 | EH5: #90C987 | EI5: #90C987 | EJ5: #90C987 | EK5: #4EB265 | EL5: #4EB265 | EM5: #4EB265 | EN5: #4EB265
A6: Publication | B6: Topic | C6: Topic | D6: Authors | E6: Topic | F6: Topic | G6: Journal | H6: Publication | I6: Publication | J6: Publication | K6: Publication | L6: Publication | M6: Authors | N6: Exclusion | O6: Full revision | P6: Revision | R6: QC | S6: driver description | T6: driver description | U6: driver description | V6: Silviculture for removals | W6: Silviculture for removals | X6: Silviculture for removals | Y6: Silviculture for removals | Z6: Silviculture for removals | AA6: Silviculture for removals | AB6: Silviculture for productivity | AC6: Silviculture for productivity | AD6: Silviculture for productivity | AE6: Silviculture for productivity | AF6: Supply chain | AG6: Supply chain | AH6: Supply chain | AI6: Supply chain | AJ6: Supply chain | AK6: Supply chain | AL6: Technology | AM6: Technology | AN6: Technology | AO6: Environmental change | AP6: Environmental change | AQ6: Environmental change | AR6: Environmental change | AS6: Environmental change | AT6: Environmental change | AU6: Demand | AV6: Demand | AW6: Demand | AX6: Demand | AY6: Demand | AZ6: QC | BA6: All | BE6: AllEnvir | BF6: AllEnvir | BG6: MainDriver | BH6: MainDriver | BI6: Wood amount | BJ6: Wood amount | BL6: Wood amount | BM6: Wood amount | BN6: Wood amount | BO6: Wood amount | BP6: Wood amount | BQ6: Wood amount | BR6: Cumulated C balance | BS6: Cumulated C balance | BT6: Cumulated C balance | BU6: Cumulated C balance | BV6: Cumulated C balance | BW6: Cumulated C balance | BX6: Cumulated C balance | BZ6: Cumulated C balance | CA6: Substitution coefficient | CB6: LCAOutcomes | CC6: biogeochemicalOutcomes | CD6: biogeochemicalOutcomes | CE6: biogeochemicalOutcomes | CF6: biogeochemicalOutcomes | CG6: biogeochemicalOutcomes | CH6: biogeochemicalOutcomes | CI6: biophysicalOutcomes | CJ6: biophysicalOutcomes | CK6: biophysicalOutcomes | CL6: biophysicalOutcomes | CM6: biophysicalOutcomes | CN6: ecologicalOutcomes | CO6: economicalOutcomes | CP6: driver description | CQ6: Wood amount | CR6: Carbon_outcome | CS6: Carbon_outcome | CU6: Carbon_outcome | CV6: Carbon_outcome | CW6: Carbon_outcome | CY6: Carbon_outcome | DA6: Carbon_outcome | DB6: Location | DC6: Location | DD6: Location | DE6: Time period | DF6: Time period | DG6: Time period | DI6: Wood affected by driver change | DJ6: Wood affected by driver change | DK6: Wood affected by driver change | DL6: Wood affected by driver change | DM6: Sector scale | DN6: QC | DO6: Wood affected by driver change | DP6: Wood affected by driver change | DQ6: Wood affected by driver change | DR6: Wood affected by driver change | DS6: Wood affected by driver change | DT6: SubstitutionShortcut | DU6: SubstitutionShortcut | DV6: SubstitutionShortcut | DW6: SubstitutionShortcut | DX6: SubstitutionShortcut | DY6: QC | DZ6: SubstitutionShortcut | EA6: Biogenic in-situ C | EB6: Biogenic in-situ C | EC6: Biogenic in-situ C | ED6: Biogenic ex-situ C | EE6: Biogenic ex-situ C | EF6: Biogenic ex-situ C | EG6: Fossil in-situ | EH6: Fossil ex-situ | EI6: Fossil ex-situ | EJ6: Fossil ex-situ | EK6: C dynamics | EL6: C dynamics | EM6: Market-based feedbacks | EN6: Market-based feedbacks | EP6: =COUNTIF($EP8:$EP1666,"Whole sector") -> 0 | EQ6: =COUNTIF($EQ8:$EQ1666,"Ecosystem approach") -> 236 | ER6: =COUNTIF($ER8:$ER1666,"Technology approach") -> 355 | EW6: QC | EX6: QC | EY6: QC | EZ6: QC | FB6: QC | FC6: DriverCheck | FD6: QCv7 | FE6: QC8_AV
A7: Source Title | B7: Author Keywords | C7: Keywords Plus | D7: Authors | E7: Article_Title | F7: Abstract | G7: Journal_ISO_Abbreviation | H7: Document type | I7: Publication_Year | J7: Times_cited | K7: DOI | L7: multipaper_index | M7: PaperID | N7: Exclusion | O7: Reviewer | P7: Reviewer2 | Q7: Extraction round | R7: ReviewerQCv7 | S7: driver definition | T7: name_ref | U7: name_alternative | V7: unmanaged forest to managed forest | W7: afforestation | X7: area subject to harvest | Y7: unspecified harvest increase | Z7: rotation length | AA7: cutting intensity | AB7: species | AC7: plantation density | AD7: fertilisation | AE7: site fertility | AF7: harvesting system | AG7: location of industry | AH7: supply chain organization | AI7: recycling | AJ7: end of life disposal | AK7: products lifespan | AL7: efficiency improvement | AM7: technologies/design switch | AN7: CCS | AO7: Water table | AP7: Temperature | AQ7: rainfall | AR7: CO2 fertilization | AS7: disturbance | AT7: N deposition | AU7: Unspecified policy | AV7: gdp, population | AW7: Exogenous wood price | AX7: Exogenous C price | AY7: exogenous land use change | AZ7: driverCheck | BA7: PracticesCheck | BB7: Nsilvicuture | BC7: Nsupplychain | BD7: Ntechnology | BE7: Ndemand | BF7: Nenvir | BG7: driver1 | BH7: driver1Cat | BI7: Qwood_stageInput | BJ7: Qwood_varInput | BK7: QwoodInPublication | BL7: Qwood_unitInput | BM7: Qwood_refInput | BN7: Qwood_alternativeInput | BO7: Qwood_ratioInput | BP7: Qwood_deltaInput | BQ7: Qwood_delta_m3woodInput | BR7: C_signInput | BS7: CInPublication | BT7: C_unitInput | BU7: C_refInput | BV7: C_alternativeInput | BW7: CratioInput | BX7: CdeltaInput | BZ7: Cdelta_tCO2Input | CA7: substitutionInput | CB7: LCA scores | CC7: CH4 | CD7: CO | CE7: N2O | CF7: Nox | CG7: Sox | CH7: VOC | CI7: Climate | CJ7: albedo | CK7: water quantity | CL7: water quality | CM7: erosion | CN7: biodiversity | CO7: price/economic welfare/social cost | CP7: Ref_check | CQ7: Qwood_ref | CR7: Qwood_alternative | CS7: Qwood_delta_m3wood | CT7: Qwood_delta_m3wood_HWP | CU7: C_ref | CV7: C_alternative | CW7: Cdelta_tCO2 | CX7: subsitution_init | CY7: substitution | CZ7: substitution_HWP | DA7: Cratio | DB7: scale | DC7: scaleAgg | DD7: country | DE7: time_start | DF7: time_end | DG7: time_length | DH7: time_horizon | DI7: UpstreamInput | DJ7: EnergyInput | DK7: PulpPaperInput | DL7: TimberInput | DM7: economy_sector | DN7: productsCheck | DO7: singleProduct | DP7: Upstream | DQ7: Energy | DR7: Pulp/Paper | DS7: Timber | DT7: self-calculated DF | DU7: displacement factor used | DV7: energy DF origin | DW7: material DF origin | DX7: overall DF origin | DY7: substitutionDFCheck | DZ7: substitution_shortcut | EA7: soilC | EB7: harv_residues | EC7: live_biomass_C | ED7: products_storage_C | EE7: eol_biogenic | EF7: off_product_biogenic | EG7: forestry_emiss | EH7: manufacturing_emiss | EI7: maintenance_emiss | EJ7: eol_fossil_emiss | EK7: biogenic_dyn | EL7: fossil_dyn | EM7: LUC_dyn | EN7: rebound_dyn | EO7: Publication quality | EP7: modelApproach | EQ7: ecosystem aproach | ER7: technology approach | ES7: C neutral forest and HWP assumption | ET7: All C | EU7: In-situ only assumption | EV7: Searchinger's assumption | EW7: Comment | EX7: Check exclusion | EY7: Outlier? | EZ7: Check outlier | FA7: Check_paradox | FB7: Check_AV | FC7: CheckSL
A8: ENVIRONMENTAL RESEARCH LETTERS | B8: forests; climate; environment; policy; bioenergy | C8: HARVEST RESIDUES; CARBON; LAND | D8: Birdsey, R; Duffy, P; Smyth, C; Akurz, W; Dugan, AJ; Houghton, R | E8: Climate, economic, and environmental impacts of producing wood for bioenergy | F8: Increasing combustion of woody biomass for electricity has raised concerns and produced conflicting statements about impacts on atmospheric greenhouse gas (GHG) concentrations, climate, and other forest values such as timber supply and biodiversity. The purposes of this concise review of current literature are to (1) examine impacts on net GHG emissions and climate from increasing bioenergy production from forests and exporting wood pellets to Europe from North America, (2) develop a set of science-based recommendations about the circumstances that would result in GHG reductions or increases in the atmosphere, and (3) identify economic and environmental impacts of increasing bioenergy use of forests. We find that increasing bioenergy production and pellet exports often increase net emissions of GHGs for decades or longer, depending on source of feedstock and its alternate fate, time horizon of analysis, energy emissions associated with the supply chain and fuel substitution, and impacts on carbon cycling of forest ecosystems. Alternative uses of roundwood often offer larger reductions in GHGs, in particular long-lived wood products that store carbon for longer periods of time and can achieve greater substitution benefits than bioenergy. Other effects of using wood for bioenergy may be considerable including induced land-use change, changes in supplies of wood and other materials for construction, albedo and non-radiative effects of land-cover change on climate, and long-term impacts on soil productivity. Changes in biodiversity and other ecosystem attributes may be strongly affected by increasing biofuel production, depending on source of material and the projected scale of biofuel production increases. | G8: Environ. Res. Lett. | I8: 2018 | K8: 10.1088/1748-9326/aab9d5 | M8: =LEFT($D8,FIND(",",$D8)-1)&"_"&I8&L8 -> Birdsey_2018 | N8: review | O8: SL | Q8: v4 | CA8: =IFERROR(BZ8/BQ8,"") | CT8: =IF(BI8="Roundwood",$CS8/2,$CS8) -> 0 | CX8: =IFERROR($CW8/$CS8,"") | CZ8: =IFERROR($CW8/$CT8,"") | EP8: =IF(AND(AND(AND(OR($EC8=1,$EB8=1),OR($EH8=1,$EF8=1)),SUM($EA8:$EE8,$EK8)>=3),SUM($EF8:$EJ8)>=2),"Whole sector approach","") | EQ8: =IF(AND(AND(OR($EC8=1,$EB8=1),AND($EH8=0,$EF8=0)),SUM($EA8:$EE8,$EK8)>=3),"Ecosystem approach","") | ER8: =IF(AND(AND(AND($EC8=0,$EB8=0),OR($EH8=1,$EF8=1)),SUM($EG8:$EJ8)>=2),"Technology approach","") | ES8: =IF(AND($EC8+$EB8+$EE8+$EA8+$EF8+$EG8=0,$N8="included"),"C neutral forest and HWP assumption","") | ET8: =IF(AND(AND(AND($EC8+$EB8+$EA8+$EG8>=2,$EF8+$EH8+$EI8>=1),$ED8+$EE8>=1),$N8="included"),"All C pools assumption","") | EU8: =IF(AND($ED8+$EE8+$EI8+$EH8+$EF8=0,$N8="included"),"In-situ only assumption","") | EX8: okVB | EY8: =IF(ISNUMBER(BW8),IF(ABS(BW8-[1]QC_indicators!$B$2)>3*[1]QC_indicators!$C$2,"C ratio",IF(ISNUMBER(CA8),IF(ABS(CA8-[1]QC_indicators!$B$1)>3*[1]QC_indicators!$C$1,"DF","no"))),IF(ISNUMBER(CA8),IF(ABS(CA8-[1]QC_indicators!$B$1)>3*[1]QC_indicators!$C$1,"DF","no"))) -> FALSE | FA8: =IF(LEN($CY8)=0,"",IF(AND($CY8<(-0.05),$ES8="C neutral forest and HWP assumption"),"Cneutral paradox",IF(AND($CY8>0.05,$EU8="In-situ only assumption"),"In-situ only paradox","")))
A9: GLOBAL CHANGE BIOLOGY | B9: carbon retention curve; carbon sequestration; cascading; climate change; first-order decay; half-life; low-carbon economy; mitigation; wood industry | C9: FOREST MANAGEMENT-PRACTICES; LIFE-CYCLE ASSESSMENT; GREENHOUSE-GAS; CLIMATE-CHANGE; ROTATION LENGTH; SEQUESTRATION; STORAGE; IMPACTS; DECOMPOSITION; DYNAMICS | D9: Brunet-Navarro, P; Jochheim, H; Muys, B | E9: Modelling carbon stocks and fluxes in the wood product sector: a comparative review | F9: In addition to forest ecosystems, wood products are carbon pools that can be strategically managed to mitigate climate change. Wood product models (WPMs) simulating the carbon balance of wood production, use and end of life can complement forest growth models to evaluate the mitigation potential of the forest sector as a whole. WPMs can be used to compare scenarios of product use and explore mitigation strategies. A considerable number of WPMs have been developed in the last three decades, but there is no review available analysing their functionality and performance. This study analyses and compares 41 WPMs. One surprising initial result was that we discovered the erroneous implementation of a few concepts and assumptions in some of the models. We further described and compared the models using six model characteristics (bucking allocation, industrial processes, carbon pools, product removal, recycling and substitution effects) and three model-use characteristics (system boundaries, model initialization and evaluation of results). Using a set of indicators based on the model characteristics, we classified models using a hierarchical clustering technique and differentiated them according to their increasing degrees of complexity and varying levels of user support. For purposes of simulating carbon stock in wood products, models with a simple structure may be sufficient, but to compare climate change mitigation options, complex models are needed. The number of models has increased substantially over the last ten years, introducing more diversity and accuracy. Calculation of substitution effects and recycling has also become more prominent. However, the lack of data is still an important constraint for a more realistic estimation of carbon stocks and fluxes. Therefore, if the sector wants to demonstrate the environmental quality of its products, it should make it a priority to provide reliable life cycle inventory data, particularly regarding aspects of time and location. | G9: Glob. Change Biol. | H9: Review | I9: 2016 | J9: 34 | K9: 10.1111/gcb.13235 | M9: =LEFT($D9,FIND(",",$D9)-1)&"_"&I9&L9 -> Brunet-Navarro_2016 | N9: review | O9: AV | Q9: v6 | CA9: =IFERROR(BZ9/BQ9,"") | CT9: =IF(BI9="Roundwood",$CS9/2,$CS9) -> 0 | CX9: =IFERROR($CW9/$CS9,"") | CZ9: =IFERROR($CW9/$CT9,"") | EP9: =IF(AND(AND(AND(OR($EC9=1,$EB9=1),OR($EH9=1,$EF9=1)),SUM($EA9:$EE9,$EK9)>=3),SUM($EF9:$EJ9)>=2),"Whole sector approach","") | EQ9: =IF(AND(AND(OR($EC9=1,$EB9=1),AND($EH9=0,$EF9=0)),SUM($EA9:$EE9,$EK9)>=3),"Ecosystem approach","") | ER9: =IF(AND(AND(AND($EC9=0,$EB9=0),OR($EH9=1,$EF9=1)),SUM($EG9:$EJ9)>=2),"Technology approach","") | ES9: =IF(AND($EC9+$EB9+$EE9+$EA9+$EF9+$EG9=0,$N9="included"),"C neutral forest and HWP assumption","") | ET9: =IF(AND(AND(AND($EC9+$EB9+$EA9+$EG9>=2,$EF9+$EH9+$EI9>=1),$ED9+$EE9>=1),$N9="included"),"All C pools assumption","") | EU9: =IF(AND($ED9+$EE9+$EI9+$EH9+$EF9=0,$N9="included"),"In-situ only assumption","") | EV9: C neutral | EY9: =IF(ISNUMBER(BW9),IF(ABS(BW9-[1]QC_indicators!$B$2)>3*[1]QC_indicators!$C$2,"C ratio",IF(ISNUMBER(CA9),IF(ABS(CA9-[1]QC_indicators!$B$1)>3*[1]QC_indicators!$C$1,"DF","no"))),IF(ISNUMBER(CA9),IF(ABS(CA9-[1]QC_indicators!$B$1)>3*[1]QC_indicators!$C$1,"DF","no"))) -> FALSE | FA9: =IF(LEN($CY9)=0,"",IF(AND($CY9<(-0.05),$ES9="C neutral forest and HWP assumption"),"Cneutral paradox",IF(AND($CY9>0.05,$EU9="In-situ only assumption"),"In-situ only paradox","")))
A10: REVISTA BRASILEIRA DE ZOOTECNIA-BRAZILIAN JOURNAL OF ANIMAL SCIENCE | B10: biological N-2 fixation; ecosystem services; grassland; nutrient cycling; tropical | C10: LEUCAENA-LEUCOCEPHALA; GLIRICIDIA-SEPIUM; ECOSYSTEM SERVICES; CONDENSED TANNINS; TROPICAL TREE; NUTRITION SECURITY; BIOMASS PRODUCTION; NITROGEN-FIXATION; FODDER TREES; N-2 FIXATION | D10: Dubeux, JCB; Muir, JP; Apolinario, VXD; Nair, PKR; Lira, MD; Sollenberger, LE | E10: Tree legumes: an underexploited resource in warm-climate silvopastures | F10: Tree legumes are an underexploited resource in warm-climate silvopastures. Perceived benefits of tree legumes include provisioning (browse/mast, timber, fuel, human food, natural medicines, and ornamentals), regulating (C sequestration, greenhouse gas mitigation, soil erosion control and riparian buffers, shade, windbreaks, and habitat for pollinators), supporting (biological N-2-fixation, nutrient cycling, soil fertility and soil health, photosynthesis, and primary productivity), and cultural ecosystem services. Tree legumes, however, have not been assessed to the same extent as herbaceous legumes. Once tree legumes are established, they are often more persistent than most herbaceous legumes. There are limitations for extended research with tree legume silvopastures, but extensive research has been done in Africa and Australia and recent efforts have been reported in South America. Economic benefits must be demonstrated to land managers to increase adoption. These benefits are apparent in the research and successes already available, but more long-term research, including the livestock component is necessary. Other factors that reduce adoption include paucity of domesticated germplasm, lag in research/technology, challenges of multipurpose trees and management complexity, challenges to mechanization, dangers of invasive weeds, and social and cultural barriers. In the current scenario of climate change and the need to increase food security, tree legumes are a key component for the sustainable intensification of livestock systems in warm-climate regions. | G10: Rev. Bras. Zootecn. | H10: Review | I10: 2017 | J10: 18 | K10: 10.1590/S1806-92902017000800010 | M10: =LEFT($D10,FIND(",",$D10)-1)&"_"&I10&L10 -> Dubeux_2017 | N10: review | O10: KN | Q10: v5 | CA10: =IFERROR(BZ10/BQ10,"") | CT10: =IF(BI10="Roundwood",$CS10/2,$CS10) -> 0 | CX10: =IFERROR($CW10/$CS10,"") | CZ10: =IFERROR($CW10/$CT10,"") | EP10: =IF(AND(AND(AND(OR($EC10=1,$EB10=1),OR($EH10=1,$EF10=1)),SUM($EA10:$EE10,$EK10)>=3),SUM($EF10:$EJ10)>=2),"Whole sector approach","") | EQ10: =IF(AND(AND(OR($EC10=1,$EB10=1),AND($EH10=0,$EF10=0)),SUM($EA10:$EE10,$EK10)>=3),"Ecosystem approach","") | ER10: =IF(AND(AND(AND($EC10=0,$EB10=0),OR($EH10=1,$EF10=1)),SUM($EG10:$EJ10)>=2),"Technology approach","") | ES10: =IF(AND($EC10+$EB10+$EE10+$EA10+$EF10+$EG10=0,$N10="included"),"C neutral forest and HWP assumption","") | ET10: =IF(AND(AND(AND($EC10+$EB10+$EA10+$EG10>=2,$EF10+$EH10+$EI10>=1),$ED10+$EE10>=1),$N10="included"),"All C pools assumption","") | EU10: =IF(AND($ED10+$EE10+$EI10+$EH10+$EF10=0,$N10="included"),"In-situ only assumption","") | EX10: okVB | EY10: =IF(ISNUMBER(BW10),IF(ABS(BW10-[1]QC_indicators!$B$2)>3*[1]QC_indicators!$C$2,"C ratio",IF(ISNUMBER(CA10),IF(ABS(CA10-[1]QC_indicators!$B$1)>3*[1]QC_indicators!$C$1,"DF","no"))),IF(ISNUMBER(CA10),IF(ABS(CA10-[1]QC_indicators!$B$1)>3*[1]QC_indicators!$C$1,"DF","no"))) -> FALSE | FA10: =IF(LEN($CY10)=0,"",IF(AND($CY10<(-0.05),$ES10="C neutral forest and HWP assumption"),"Cneutral paradox",IF(AND($CY10>0.05,$EU10="In-situ only assumption"),"In-situ only paradox","")))
A11: INTERNATIONAL JOURNAL OF LIFE CYCLE ASSESSMENT | B11: Ghanaian timber sector; Environmental performance indicators; Functional units; Life cycle impact assessment (LCIA); Tropical wood | C11: LAND-USE IMPACT; ENVIRONMENTAL-IMPACT; WOOD WASTES; INVENTORY; BIODIVERSITY; METHODOLOGY; PRODUCTS | D11: Eshun, JF; Potting, J; Leemans, R | E11: LCA of the timber sector in Ghana: preliminary life cycle impact assessment (LCIA) | F11: Purpose Most life cycle impact assessment (LCIA) approaches in life cycle assessment (LCA) are developed for western countries. Their LCIA approaches and characterization methodologies for different impact categories may not be necessarily relevant to African environmental conditions and particularly not for the timber sector in Ghana. This study reviews the relevance of existing impact categories and LCIA approaches, and uses the most relevant for the timber sector of Ghana. Materials and methods The study reviewed 23 life cycle inventories (LCIs) and LCAs on forestry, timber, and wood products for relevant impact categories and LCIA approaches for their relevance to the specific conditions in Ghana. This study uses an earlier LCI study of the timber industry as a starting point for an additional LCIA. We next performed a correlation and regression analysis to learn whether wood wastes may function as a reasonable single indicator for land use as proxy for biodiversity loss and the other impact categories. Results and discussion The literature review shows that no LCI or LCA studies were developed for Africa or the tropics. The LCIA approaches in the reviewed LCAs are indeed shown to take their basis in the environmental problems in western countries and characterization methodologies relating to how these problems manifest themselves in the western world. Characterization methodologies for different impact categories in CML-2000 and other LCIA approaches may not be necessarily relevant to African tropical environmental conditions and particularly not for the timber sector in Ghana. This situation hampers the reliability of our LCIA and points to a serious research gap in LCIA development in general. We applied the scientifically well-recognized CML 2000 to the earlier LCI results and characterized the preliminary selected impact categories of global warming, acidification, eutrophication, photochemical oxidant formation, and human toxicity. The correlation analysis indicated that wood waste is indeed strongly correlated with land use as proxy for biodiversity loss and also positively correlated with the other five potential impact results. It can be concluded that wood waste production is a major driving force for biodiversity loss and a sufficiently good single indicator for all other environmental performance indicators in the timber sector of Ghana. Conclusions This study and the previous LCI paper are pioneering a field not yet explored, since the correct environmental performance indicators are not yet developed or adapted to tropical conditions. The development of LCIA approaches in the tropics may be the start of a never-ending journey in LCA research in Africa, particularly Ghana. | G11: Int. J. Life Cycle Assess. | H11: Article | I11: 2011 | J11: 15 | K11: 10.1007/s11367-011-0307-5 | M11: =LEFT($D11,FIND(",",$D11)-1)&"_"&I11&L11 -> Eshun_2011 | N11: review | O11: SC | P11: AV | Q11: v6 | CA11: =IFERROR(BZ11/BQ11,"") | CT11: =IF(BI11="Roundwood",$CS11/2,$CS11) -> 0 | CX11: =IFERROR($CW11/$CS11,"") | CZ11: =IFERROR($CW11/$CT11,"") | EP11: =IF(AND(AND(AND(OR($EC11=1,$EB11=1),OR($EH11=1,$EF11=1)),SUM($EA11:$EE11,$EK11)>=3),SUM($EF11:$EJ11)>=2),"Whole sector approach","") | EQ11: =IF(AND(AND(OR($EC11=1,$EB11=1),AND($EH11=0,$EF11=0)),SUM($EA11:$EE11,$EK11)>=3),"Ecosystem approach","") | ER11: =IF(AND(AND(AND($EC11=0,$EB11=0),OR($EH11=1,$EF11=1)),SUM($EG11:$EJ11)>=2),"Technology approach","") | ES11: =IF(AND($EC11+$EB11+$EE11+$EA11+$EF11+$EG11=0,$N11="included"),"C neutral forest and HWP assumption","") | ET11: =IF(AND(AND(AND($EC11+$EB11+$EA11+$EG11>=2,$EF11+$EH11+$EI11>=1),$ED11+$EE11>=1),$N11="included"),"All C pools assumption","") | EU11: =IF(AND($ED11+$EE11+$EI11+$EH11+$EF11=0,$N11="included"),"In-situ only assumption","") | EW11: not a review per se but duplicates results from Eshun 2010 | EY11: =IF(ISNUMBER(BW11),IF(ABS(BW11-[1]QC_indicators!$B$2)>3*[1]QC_indicators!$C$2,"C ratio",IF(ISNUMBER(CA11),IF(ABS(CA11-[1]QC_indicators!$B$1)>3*[1]QC_indicators!$C$1,"DF","no"))),IF(ISNUMBER(CA11),IF(ABS(CA11-[1]QC_indicators!$B$1)>3*[1]QC_indicators!$C$1,"DF","no"))) -> FALSE | FA11: =IF(LEN($CY11)=0,"",IF(AND($CY11<(-0.05),$ES11="C neutral forest and HWP assumption"),"Cneutral paradox",IF(AND($CY11>0.05,$EU11="In-situ only assumption"),"In-situ only paradox","")))
A12: FOREST POLICY AND ECONOMICS | B12: Climate change; Harvested wood products; Carbon stocks and emissions; Wood substitute | C12: FOREST BIOENERGY; LIFE-CYCLE; ENERGY USE; EMISSIONS; SEQUESTRATION; CONSTRUCTION; MANAGEMENT; IMPACTS; CLIMATE; BUDGET | D12: Geng, AX; Yang, HQ; Chen, JX; Hong, YX | E12: Review of carbon storage function of harvested wood products and the potential of wood substitution in greenhouse gas mitigation | F12: Global forests have the potential to significantly increase or reduce atmospheric greenhouse gas (GHG) concentration. Harvested wood products (HWP) are an important part of the forest-atmosphere carbon cycle. On the one hand, HWP can retain the carbon for various periods of time, depending on the end uses. On the other hand, using HWP in place of more GHG-intensive materials and using wood bioenergy to substitute for fossil fuels result in reduced fossil fuel emissions. However, critical methodological differences exist in existing literature in assessing the GHG effects of HWP and wood bioenergy substitution, and large diversity in system boundary, substitution scenario, study period, and reference baseline results in large difference in reported GHG effects of wood substitution. In the present study, we conducted a comprehensive literature review to (a) clarify the methodological issues in GHG effects assessments of HWP and wood bioenergy substitution, (b) summarize and compare the reported GHG effects, and (c) identify knowledge gaps to inform future research. We support the conclusion that to accurately assess the GHG effects, HWP and wood bioenergy life-cycle carbon analysis needs to be integrated with forest carbon balance analysis. Substituting HWP for non-wood materials appears to be more effective in reducing GHG emissions than substituting wood for fossil fuels. The time required to obtain net emission reduction for wood bioenergy in place of fossil fuels can be 0 years, decades or more than a century, depending on forest biomass sources (e.g., harvest residue, standing live trees) and fossil fuels displaced. For HWP used to replace non-wood material, however, the time required to obtain net emission reduction largely remains a future research need. Overall, HWP and wood bioenergy originated from sustainably managed forests can significantly contribute to GHG emissions reduction in the long term. | G12: Forest Policy Econ. | H12: Article | I12: 2017 | J12: 50 | K12: 10.1016/j.forpol.2017.08.007 | M12: =LEFT($D12,FIND(",",$D12)-1)&"_"&I12&L12 -> Geng_2017 | N12: review | O12: SL | Q12: v5 | CA12: =IFERROR(BZ12/BQ12,"") | CT12: =IF(BI12="Roundwood",$CS12/2,$CS12) -> 0 | CX12: =IFERROR($CW12/$CS12,"") | CZ12: =IFERROR($CW12/$CT12,"") | EP12: =IF(AND(AND(AND(OR($EC12=1,$EB12=1),OR($EH12=1,$EF12=1)),SUM($EA12:$EE12,$EK12)>=3),SUM($EF12:$EJ12)>=2),"Whole sector approach","") | EQ12: =IF(AND(AND(OR($EC12=1,$EB12=1),AND($EH12=0,$EF12=0)),SUM($EA12:$EE12,$EK12)>=3),"Ecosystem approach","") | ER12: =IF(AND(AND(AND($EC12=0,$EB12=0),OR($EH12=1,$EF12=1)),SUM($EG12:$EJ12)>=2),"Technology approach","") | ES12: =IF(AND($EC12+$EB12+$EE12+$EA12+$EF12+$EG12=0,$N12="included"),"C neutral forest and HWP assumption","") | ET12: =IF(AND(AND(AND($EC12+$EB12+$EA12+$EG12>=2,$EF12+$EH12+$EI12>=1),$ED12+$EE12>=1),$N12="included"),"All C pools assumption","") | EU12: =IF(AND($ED12+$EE12+$EI12+$EH12+$EF12=0,$N12="included"),"In-situ only assumption","") | EX12: disagree: it is an original LCA paper. It combines existing LCAs on raw materials to compare a baseline with a "high HWP" scenario | EY12: =IF(ISNUMBER(BW12),IF(ABS(BW12-[1]QC_indicators!$B$2)>3*[1]QC_indicators!$C$2,"C ratio",IF(ISNUMBER(CA12),IF(ABS(CA12-[1]QC_indicators!$B$1)>3*[1]QC_indicators!$C$1,"DF","no"))),IF(ISNUMBER(CA12),IF(ABS(CA12-[1]QC_indicators!$B$1)>3*[1]QC_indicators!$C$1,"DF","no"))) -> FALSE | FA12: =IF(LEN($CY12)=0,"",IF(AND($CY12<(-0.05),$ES12="C neutral forest and HWP assumption"),"Cneutral paradox",IF(AND($CY12>0.05,$EU12="In-situ only assumption"),"In-situ only paradox","")))
A13: FOREST POLICY AND ECONOMICS | B13: Climate change; Harvested wood products; Carbon stocks and emissions; Wood substitute | C13: FOREST BIOENERGY; LIFE-CYCLE; ENERGY USE; EMISSIONS; SEQUESTRATION; CONSTRUCTION; MANAGEMENT; IMPACTS; CLIMATE; BUDGET | D13: Geng, AX; Yang, HQ; Chen, JX; Hong, YX | E13: Review of carbon storage function of harvested wood products and the potential of wood substitution in greenhouse gas mitigation | F13: Global forests have the potential to significantly increase or reduce atmospheric greenhouse gas (GHG) concentration. Harvested wood products (HWP) are an important part of the forest-atmosphere carbon cycle. On the one hand, HWP can retain the carbon for various periods of time, depending on the end uses. On the other hand, using HWP in place of more GHG-intensive materials and using wood bioenergy to substitute for fossil fuels result in reduced fossil fuel emissions. However, critical methodological differences exist in existing literature in assessing the GHG effects of HWP and wood bioenergy substitution, and large diversity in system boundary, substitution scenario, study period, and reference baseline results in large difference in reported GHG effects of wood substitution. In the present study, we conducted a comprehensive literature review to (a) clarify the methodological issues in GHG effects assessments of HWP and wood bioenergy substitution, (b) summarize and compare the reported GHG effects, and (c) identify knowledge gaps to inform future research. We support the conclusion that to accurately assess the GHG effects, HWP and wood bioenergy life-cycle carbon analysis needs to be integrated with forest carbon balance analysis. Substituting HWP for non-wood materials appears to be more effective in reducing GHG emissions than substituting wood for fossil fuels. The time required to obtain net emission reduction for wood bioenergy in place of fossil fuels can be 0 years, decades or more than a century, depending on forest biomass sources (e.g., harvest residue, standing live trees) and fossil fuels displaced. For HWP used to replace non-wood material, however, the time required to obtain net emission reduction largely remains a future research need. Overall, HWP and wood bioenergy originated from sustainably managed forests can significantly contribute to GHG emissions reduction in the long term. | G13: Forest Policy Econ. | H13: Article | I13: 2017 | J13: 50 | K13: 10.1016/j.forpol.2017.08.007 | M13: =LEFT($D13,FIND(",",$D13)-1)&"_"&I13&L13 -> Geng_2017 | N13: review | O13: SL | P13: AV | Q13: v6 | CA13: =IFERROR(BZ13/BQ13,"") | CT13: =IF(BI13="Roundwood",$CS13/2,$CS13) -> 0 | CX13: =IFERROR($CW13/$CS13,"") | CZ13: =IFERROR($CW13/$CT13,"") | EP13: =IF(AND(AND(AND(OR($EC13=1,$EB13=1),OR($EH13=1,$EF13=1)),SUM($EA13:$EE13,$EK13)>=3),SUM($EF13:$EJ13)>=2),"Whole sector approach","") | EQ13: =IF(AND(AND(OR($EC13=1,$EB13=1),AND($EH13=0,$EF13=0)),SUM($EA13:$EE13,$EK13)>=3),"Ecosystem approach","") | ER13: =IF(AND(AND(AND($EC13=0,$EB13=0),OR($EH13=1,$EF13=1)),SUM($EG13:$EJ13)>=2),"Technology approach","") | ES13: =IF(AND($EC13+$EB13+$EE13+$EA13+$EF13+$EG13=0,$N13="included"),"C neutral forest and HWP assumption","") | ET13: =IF(AND(AND(AND($EC13+$EB13+$EA13+$EG13>=2,$EF13+$EH13+$EI13>=1),$ED13+$EE13>=1),$N13="included"),"All C pools assumption","") | EU13: =IF(AND($ED13+$EE13+$EI13+$EH13+$EF13=0,$N13="included"),"In-situ only assumption","") | EY13: =IF(ISNUMBER(BW13),IF(ABS(BW13-[1]QC_indicators!$B$2)>3*[1]QC_indicators!$C$2,"C ratio",IF(ISNUMBER(CA13),IF(ABS(CA13-[1]QC_indicators!$B$1)>3*[1]QC_indicators!$C$1,"DF","no"))),IF(ISNUMBER(CA13),IF(ABS(CA13-[1]QC_indicators!$B$1)>3*[1]QC_indicators!$C$1,"DF","no"))) -> FALSE | FA13: =IF(LEN($CY13)=0,"",IF(AND($CY13<(-0.05),$ES13="C neutral forest and HWP assumption"),"Cneutral paradox",IF(AND($CY13>0.05,$EU13="In-situ only assumption"),"In-situ only paradox","")))
A14: SUSTAINABILITY | B14: cross-laminated timber; life-cycle assessment; mass timber building; whole-building LCA methodology | D14: Gu, HM; Liang, SB; Pierobon, F; Puettmann, M; Ganguly, I; Chen, CY; Pasternack, R; Wishnie, M; Jones, S; Maples, I | E14: Mass Timber Building Life Cycle Assessment Methodology for the US Regional Case Studies | F14: The building industry currently consumes over a third of energy produced and emits 39% of greenhouse gases globally produced by human activities. The manufacturing of building materials and the construction of buildings make up 11% of those emissions within the sector. Whole-building life-cycle assessment is a holistic and scientific tool to assess multiple environmental impacts with internationally accepted inventory databases. A comparison of the building life-cycle assessment results would help to select materials and designs to reduce total environmental impacts at the early planning stage for architects and developers, and to revise the building code to improve environmental performance. The Nature Conservancy convened a group of researchers and policymakers from governments and non-profit organizations with expertise across wood product life-cycle assessment, forest carbon, and forest products market analysis to address emissions and energy consumption associated with mass timber building solutions. The study disclosed a series of detailed, comparative life-cycle assessments of pairs of buildings using both mass timber and conventional materials. The methodologies used in this study are clearly laid out in this paper for transparency and accountability. A plethora of data exists on the favorable environmental performance of wood as a building material and energy source, and many opportunities appear for research to improve on current practices. | G14: Sustainability | H14: Article | I14: 2021 | J14: 0 | K14: 10.3390/su132414034 | M14: =LEFT($D14,FIND(",",$D14)-1)&"_"&I14&L14 -> Gu_2021 | N14: review | O14: TH | Q14: v5 | CA14: =IFERROR(BZ14/BQ14,"") | CT14: =IF(BI14="Roundwood",$CS14/2,$CS14) -> 0 | CX14: =IFERROR($CW14/$CS14,"") | CZ14: =IFERROR($CW14/$CT14,"") | EP14: =IF(AND(AND(AND(OR($EC14=1,$EB14=1),OR($EH14=1,$EF14=1)),SUM($EA14:$EE14,$EK14)>=3),SUM($EF14:$EJ14)>=2),"Whole sector approach","") | EQ14: =IF(AND(AND(OR($EC14=1,$EB14=1),AND($EH14=0,$EF14=0)),SUM($EA14:$EE14,$EK14)>=3),"Ecosystem approach","") | ER14: =IF(AND(AND(AND($EC14=0,$EB14=0),OR($EH14=1,$EF14=1)),SUM($EG14:$EJ14)>=2),"Technology approach","") | ES14: =IF(AND($EC14+$EB14+$EE14+$EA14+$EF14+$EG14=0,$N14="included"),"C neutral forest and HWP assumption","") | ET14: =IF(AND(AND(AND($EC14+$EB14+$EA14+$EG14>=2,$EF14+$EH14+$EI14>=1),$ED14+$EE14>=1),$N14="included"),"All C pools assumption","") | EU14: =IF(AND($ED14+$EE14+$EI14+$EH14+$EF14=0,$N14="included"),"In-situ only assumption","") | EX14: okVB | EY14: =IF(ISNUMBER(BW14),IF(ABS(BW14-[1]QC_indicators!$B$2)>3*[1]QC_indicators!$C$2,"C ratio",IF(ISNUMBER(CA14),IF(ABS(CA14-[1]QC_indicators!$B$1)>3*[1]QC_indicators!$C$1,"DF","no"))),IF(ISNUMBER(CA14),IF(ABS(CA14-[1]QC_indicators!$B$1)>3*[1]QC_indicators!$C$1,"DF","no"))) -> FALSE | FA14: =IF(LEN($CY14)=0,"",IF(AND($CY14<(-0.05),$ES14="C neutral forest and HWP assumption"),"Cneutral paradox",IF(AND($CY14>0.05,$EU14="In-situ only assumption"),"In-situ only paradox","")))
A15: SUSTAINABILITY | B15: structural and engineered timber; life cycle assessment; harvested wood products; carbon storage; built environment; climate change mitigation | C15: LIFE-CYCLE ASSESSMENT; CLIMATE-CHANGE; CARBON MITIGATION; BUILT ENVIRONMENT; EMBODIED CARBON; BIOGENIC CARBON; COMPARATIVE LCA; WOOD PRODUCTS; LAND-USE; IMPACT | D15: Hart, J; Pomponi, F | E15: More Timber in Construction: Unanswered Questions and Future Challenges | F15: The built environment is one of the greatest contributors to carbon emissions, climate change, and to the unsustainable pressure on the natural environment and its ecosystems. The use of more timber in construction is one possible response, and an authoritative contribution to this growing movement comes from the UK's Committee on Climate Change, which identifies a substantial increase in the use of wood in the construction of buildings as a top priority. However, a global encouragement of such a strategy raises some difficult questions. Given the urgency of effective solutions for low-carbon built environments, and the likely continued growth in demand for timber in construction, this article reviews its sustainability and identifies future challenges and unanswered questions. Existing evidence points indeed towards timber as the lower carbon option when modelled through life cycle assessment without having to draw on arguments around carbon storage. Issues however remain on the timing of carbon emissions, land allocation, and the environmental loads and benefits associated with the end-of-life options: analysis of environmental product declarations for engineered timber suggests that landfill might either be the best or the worst option from a climate change perspective, depending on assumptions. | G15: Sustainability | H15: Article | I15: 2020 | J15: 11 | K15: 10.3390/su12083473 | M15: =LEFT($D15,FIND(",",$D15)-1)&"_"&I15&L15 -> Hart_2020 | N15: review | O15: TH | Q15: v5 | CA15: =IFERROR(BZ15/BQ15,"") | CT15: =IF(BI15="Roundwood",$CS15/2,$CS15) -> 0 | CX15: =IFERROR($CW15/$CS15,"") | CZ15: =IFERROR($CW15/$CT15,"") | EP15: =IF(AND(AND(AND(OR($EC15=1,$EB15=1),OR($EH15=1,$EF15=1)),SUM($EA15:$EE15,$EK15)>=3),SUM($EF15:$EJ15)>=2),"Whole sector approach","") | EQ15: =IF(AND(AND(OR($EC15=1,$EB15=1),AND($EH15=0,$EF15=0)),SUM($EA15:$EE15,$EK15)>=3),"Ecosystem approach","") | ER15: =IF(AND(AND(AND($EC15=0,$EB15=0),OR($EH15=1,$EF15=1)),SUM($EG15:$EJ15)>=2),"Technology approach","") | ES15: =IF(AND($EC15+$EB15+$EE15+$EA15+$EF15+$EG15=0,$N15="included"),"C neutral forest and HWP assumption","") | ET15: =IF(AND(AND(AND($EC15+$EB15+$EA15+$EG15>=2,$EF15+$EH15+$EI15>=1),$ED15+$EE15>=1),$N15="included"),"All C pools assumption","") | EU15: =IF(AND($ED15+$EE15+$EI15+$EH15+$EF15=0,$N15="included"),"In-situ only assumption","") | EX15: okVB | EY15: =IF(ISNUMBER(BW15),IF(ABS(BW15-[1]QC_indicators!$B$2)>3*[1]QC_indicators!$C$2,"C ratio",IF(ISNUMBER(CA15),IF(ABS(CA15-[1]QC_indicators!$B$1)>3*[1]QC_indicators!$C$1,"DF","no"))),IF(ISNUMBER(CA15),IF(ABS(CA15-[1]QC_indicators!$B$1)>3*[1]QC_indicators!$C$1,"DF","no"))) -> FALSE | FA15: =IF(LEN($CY15)=0,"",IF(AND($CY15<(-0.05),$ES15="C neutral forest and HWP assumption"),"Cneutral paradox",IF(AND($CY15>0.05,$EU15="In-situ only assumption"),"In-situ only paradox","")))
A16: LAND | B16: wood-based products; circular bioeconomy; market development; climate change impacts; environmental sustainability | C16: LIFE-CYCLE ASSESSMENT; KRAFT PULP-MILL; CRUDE TALL OIL; GREENHOUSE-GAS; GLOBAL PAPER; MARKET; BIODIVERSITY; CHEMICALS; INDUSTRY; IMPACTS | D16: Hassegawa, M; Van Brusselen, J; Cramm, M; Verkerk, PJ | E16: Wood-Based Products in the Circular Bioeconomy: Status and Opportunities towards Environmental Sustainability | F16: The circular bioeconomy offers solutions to curb the effects of climate change by focusing on the use of renewable, biological resources to produce food, energy, materials, and services. The substitution of fossil products by wood-based products can help avoid or reduce greenhouse gas emissions over the life cycle of products. However, it is important to understand the potential impacts of large-scale material substitution at the market level. This study aimed to assess the role of selected wood-based products in the circular bioeconomy, the possible changes in their markets, and investigate which elements could ensure the environmental sustainability of these products. The demand for graphic paper has declined over the last 15 years, while the demand for packaging has increased. Cross-laminated timber and man-made cellulosic fibres have seen their global consumption increase over the last decade. While there are benefits associated with the substitution of non-renewable materials by wood-based products, there is still limited understanding of the substitution effects at market-, country- and global level. Some factors enabling the further uptake of wood-based products include initiatives that stimulate technological change, incentives to produce or consume less fossil-based and more bio-based alternatives, and the promotion and marketing of wood-based products as viable alternatives to non-renewable materials. | G16: Land | H16: Article | I16: 2022 | J16: 1 | K16: 10.3390/land11122131 | M16: =LEFT($D16,FIND(",",$D16)-1)&"_"&I16&L16 -> Hassegawa_2022 | N16: review | O16: AV | Q16: v6 | AZ16: =COUNTIF(X16:AY16,"<>0") -> 28 | BA16: =COUNTIF(X16:AN16,"<>0") -> 17 | CA16: =IFERROR(BZ16/BQ16,"") | CT16: =IF(BI16="Roundwood",$CS16/2,$CS16) -> 0 | CX16: =IFERROR($CW16/$CS16,"") | CZ16: =IFERROR($CW16/$CT16,"") | EP16: =IF(AND(AND(AND(OR($EC16=1,$EB16=1),OR($EH16=1,$EF16=1)),SUM($EA16:$EE16,$EK16)>=3),SUM($EF16:$EJ16)>=2),"Whole sector approach","") | EQ16: =IF(AND(AND(OR($EC16=1,$EB16=1),AND($EH16=0,$EF16=0)),SUM($EA16:$EE16,$EK16)>=3),"Ecosystem approach","") | ER16: =IF(AND(AND(AND($EC16=0,$EB16=0),OR($EH16=1,$EF16=1)),SUM($EG16:$EJ16)>=2),"Technology approach","") | ES16: =IF(AND($EC16+$EB16+$EE16+$EA16+$EF16+$EG16=0,$N16="included"),"C neutral forest and HWP assumption","") | ET16: =IF(AND(AND(AND($EC16+$EB16+$EA16+$EG16>=2,$EF16+$EH16+$EI16>=1),$ED16+$EE16>=1),$N16="included"),"All C pools assumption","") | EU16: =IF(AND($ED16+$EE16+$EI16+$EH16+$EF16=0,$N16="included"),"In-situ only assumption","") | EY16: =IF(ISNUMBER(BW16),IF(ABS(BW16-[1]QC_indicators!$B$2)>3*[1]QC_indicators!$C$2,"C ratio",IF(ISNUMBER(CA16),IF(ABS(CA16-[1]QC_indicators!$B$1)>3*[1]QC_indicators!$C$1,"DF","no"))),IF(ISNUMBER(CA16),IF(ABS(CA16-[1]QC_indicators!$B$1)>3*[1]QC_indicators!$C$1,"DF","no"))) -> FALSE | FA16: =IF(LEN($CY16)=0,"",IF(AND($CY16<(-0.05),$ES16="C neutral forest and HWP assumption"),"Cneutral paradox",IF(AND($CY16>0.05,$EU16="In-situ only assumption"),"In-situ only paradox","")))
A17: ENVIRONMENTAL RESEARCH LETTERS | B17: circular economy; climate change mitigation; life cycle assessment; industrial policy; resource efficiency; cement; iron and steel | C17: LIFE-CYCLE ASSESSMENT; COMPARING ENVIRONMENTAL IMPACTS; PRINTED-CIRCUIT BOARDS; MATERIAL FLOW-ANALYSIS; DEMOLITION WASTE; ENERGY DEMAND; STEEL REUSE; RESIDENTIAL BUILDINGS; BUILT ENVIRONMENT; EMBODIED ENERGY | D17: Hertwich, EG; Ali, S; Ciacci, L; Fishman, T; Heeren, N; Masanet, E; Asghari, FN; Olivetti, E; Pauliuk, S; Tu, QS; Wolfram, P | E17: Material efficiency strategies to reducing greenhouse gas emissions associated with buildings, vehicles, and electronics-a review | F17: As one quarter of global energy use serves the production of materials, the more efficient use of these materials presents a significant opportunity for the mitigation of greenhouse gas (GHG) emissions. With the renewed interest of policy makers in the circular economy, material efficiency (ME) strategies such as light-weighting and downsizing of and lifetime extension for products, reuse and recycling of materials, and appropriate material choice are being promoted. Yet, the emissions savings from ME remain poorly understood, owing in part to the multitude of material uses and diversity of circumstances and in part to a lack of analytical effort. We have reviewed emissions reductions from ME strategies applied to buildings, cars, and electronics. We find that there can be a systematic trade-off between material use in the production of buildings, vehicles, and appliances and energy use in their operation, requiring a careful life cycle assessment of ME strategies. We find that the largest potential emission reductions quantified in the literature result from more intensive use of and lifetime extension for buildings and the light-weighting and reduced size of vehicles. Replacing metals and concrete with timber in construction can result in significant GHG benefits, but trade-offs and limitations to the potential supply of timber need to be recognized. Repair and remanufacturing of products can also result in emission reductions, which have been quantified only on a case-by-case basis and are difficult to generalize. The recovery of steel, aluminum, and copper from building demolition waste and the end-of-life vehicles and appliances already results in the recycling of base metals, which achieves significant emission reductions. Higher collection rates, sorting efficiencies, and the alloy-specific sorting of metals to preserve the function of alloying elements while avoiding the contamination of base metals are important steps to further reduce emissions. | G17: Environ. Res. Lett. | H17: Review | I17: 2019 | J17: 79 | K17: 10.1088/1748-9326/ab0fe3 | M17: =LEFT($D17,FIND(",",$D17)-1)&"_"&I17&L17 -> Hertwich_2019 | N17: review | O17: SC | Q17: v5 | CA17: =IFERROR(BZ17/BQ17,"") | CT17: =IF(BI17="Roundwood",$CS17/2,$CS17) -> 0 | CX17: =IFERROR($CW17/$CS17,"") | CZ17: =IFERROR($CW17/$CT17,"") | EP17: =IF(AND(AND(AND(OR($EC17=1,$EB17=1),OR($EH17=1,$EF17=1)),SUM($EA17:$EE17,$EK17)>=3),SUM($EF17:$EJ17)>=2),"Whole sector approach","") | EQ17: =IF(AND(AND(OR($EC17=1,$EB17=1),AND($EH17=0,$EF17=0)),SUM($EA17:$EE17,$EK17)>=3),"Ecosystem approach","") | ER17: =IF(AND(AND(AND($EC17=0,$EB17=0),OR($EH17=1,$EF17=1)),SUM($EG17:$EJ17)>=2),"Technology approach","") | ES17: =IF(AND($EC17+$EB17+$EE17+$EA17+$EF17+$EG17=0,$N17="included"),"C neutral forest and HWP assumption","") | ET17: =IF(AND(AND(AND($EC17+$EB17+$EA17+$EG17>=2,$EF17+$EH17+$EI17>=1),$ED17+$EE17>=1),$N17="included"),"All C pools assumption","") | EU17: =IF(AND($ED17+$EE17+$EI17+$EH17+$EF17=0,$N17="included"),"In-situ only assumption","") | EX17: okVB | EY17: =IF(ISNUMBER(BW17),IF(ABS(BW17-[1]QC_indicators!$B$2)>3*[1]QC_indicators!$C$2,"C ratio",IF(ISNUMBER(CA17),IF(ABS(CA17-[1]QC_indicators!$B$1)>3*[1]QC_indicators!$C$1,"DF","no"))),IF(ISNUMBER(CA17),IF(ABS(CA17-[1]QC_indicators!$B$1)>3*[1]QC_indicators!$C$1,"DF","no"))) -> FALSE | FA17: =IF(LEN($CY17)=0,"",IF(AND($CY17<(-0.05),$ES17="C neutral forest and HWP assumption"),"Cneutral paradox",IF(AND($CY17>0.05,$EU17="In-situ only assumption"),"In-situ only paradox","")))
D18: Hurmekoski, E., Smyth, C., Stern, T., Verkerk, P. J., & Asada, R. | E18: Substitution impacts of wood use at the market level: a systematic review | G18: Environmental Research Letters | I18: 2021 | K18: 10.1088/1748-9326/ac386f | M18: =LEFT($D18,FIND(",",$D18)-1)&"_"&I18&L18 -> Hurmekoski_2021 | N18: review | O18: AV | Q18: v5 | CA18: =IFERROR(BZ18/BQ18,"") | CT18: =IF(BI18="Roundwood",$CS18/2,$CS18) -> 0 | CX18: =IFERROR($CW18/$CS18,"") | CZ18: =IFERROR($CW18/$CT18,"") | EP18: =IF(AND(AND(AND(OR($EC18=1,$EB18=1),OR($EH18=1,$EF18=1)),SUM($EA18:$EE18,$EK18)>=3),SUM($EF18:$EJ18)>=2),"Whole sector approach","") | EQ18: =IF(AND(AND(OR($EC18=1,$EB18=1),AND($EH18=0,$EF18=0)),SUM($EA18:$EE18,$EK18)>=3),"Ecosystem approach","") | ER18: =IF(AND(AND(AND($EC18=0,$EB18=0),OR($EH18=1,$EF18=1)),SUM($EG18:$EJ18)>=2),"Technology approach","") | ES18: =IF(AND($EC18+$EB18+$EE18+$EA18+$EF18+$EG18=0,$N18="included"),"C neutral forest and HWP assumption","") | ET18: =IF(AND(AND(AND($EC18+$EB18+$EA18+$EG18>=2,$EF18+$EH18+$EI18>=1),$ED18+$EE18>=1),$N18="included"),"All C pools assumption","") | EU18: =IF(AND($ED18+$EE18+$EI18+$EH18+$EF18=0,$N18="included"),"In-situ only assumption","") | EY18: =IF(ISNUMBER(BW18),IF(ABS(BW18-[1]QC_indicators!$B$2)>3*[1]QC_indicators!$C$2,"C ratio",IF(ISNUMBER(CA18),IF(ABS(CA18-[1]QC_indicators!$B$1)>3*[1]QC_indicators!$C$1,"DF","no"))),IF(ISNUMBER(CA18),IF(ABS(CA18-[1]QC_indicators!$B$1)>3*[1]QC_indicators!$C$1,"DF","no"))) -> FALSE | FA18: =IF(LEN($CY18)=0,"",IF(AND($CY18<(-0.05),$ES18="C neutral forest and HWP assumption"),"Cneutral paradox",IF(AND($CY18>0.05,$EU18="In-situ only assumption"),"In-situ only paradox","")))
